Workbook
Name tx_Since: 'Final Project Dataset'!$M$2:$M$251
Name tx_Price: 'Final Project Dataset'!$I$2:$I$251
Name tx_ProdID: 'Final Project Dataset'!$E$2:$E$251
Name tx_Total: 'Final Project Dataset'!$N$2:$N$251
Name tx_Segment: 'Final Project Dataset'!$L$2:$L$251
Name tx_Region: 'Final Project Dataset'!$K$2:$K$251
Name tx_Qty: 'Final Project Dataset'!$H$2:$H$251
Name tx_CustName: 'Final Project Dataset'!$D$2:$D$251
Name tx_Product: 'Final Project Dataset'!$F$2:$F$251
Name tx_Category: 'Final Project Dataset'!$G$2:$G$251
Name tx_Pay: 'Final Project Dataset'!$J$2:$J$251
Name tx_Date: 'Final Project Dataset'!$B$2:$B$251
Name tx_CustID: 'Final Project Dataset'!$C$2:$C$251
Name tx_ID: 'Final Project Dataset'!$A$2:$A$251

Sheet Project Instructions
A1: PR. Final Project - "Data Intelligence Dashboard"
A2: Dataset: Use the 'Final Project Dataset' sheet containing 200+ records of customer transactions. Objective: Create a full-fledged analysis and reporting solution using Excel to analyze customer transactions, find insights, and build visualizations and dashboards. Key Topics to Implement: - Date & Time Functions: TODAY, NOW, DATEDIF, EOMONTH - FILTER Function for multi-value returns - Conditional Formatting with Icons/Arrows - Create Timestamp (using NOW and iterative calculations) - WHAT-IF Analysis: Scenario Manager, Goal Seek - Linear Regression using Data Analysis Toolpak - Data Analysis & Storytelling from the dataset - Use GroupBy concepts to find High-Value Customers using formulas - Create Dashboard using: - Pivot Tables - Pivot Charts (Bar, Line, Pie) - Slicers and Timelines - KPI Indicators with Conditional Formatting - Find most frequently purchased product or repeating names using formulas - Compare two lists and extract matching names in a new column - Create Abbreviations using TEXT functions - Build a final report with insights and storytelling Deliverable: - Well-structured workbook with multiple sheets (Raw Data, Analysis, Visualizations, Dashboard) - Summary Insights with key metrics: Total Revenue, Top Customers, Most Sold Products, Regional Sales - Use of all required formulas and functions as listed above

Sheet Final Project Dataset
A1: Transaction_ID | B1: Date | C1: Customer_ID | D1: Customer_Name | E1: Product_ID | F1: Product_Name | G1: Category | H1: Quantity | I1: Unit_Price | J1: Payment_Method | K1: Region | L1: Customer_Segment | M1: Customer_Since | N1: Total_Amount
A2: TRX0155 | B2: 45393 | C2: CUST023 | D2: Paul Baker | E2: P009 | F2: Monitor | G2: Electronics | H2: 3 | I2: 249.99 | J2: Cash | K2: Central | L2: Basic | M2: 44425 | N2: 749.97
A3: TRX0023 | B3: 45396 | C3: CUST013 | D3: Joseph Jackson | E3: P009 | F3: Monitor | G3: Electronics | H3: 3 | I3: 249.99 | J3: Credit Card | K3: Central | L3: Premium | M3: 44575 | N3: 749.97
A4: TRX0139 | B4: 45399 | C4: CUST021 | D4: Kevin Scott | E4: P005 | F4: Blender | G4: Appliances | H4: 3 | I4: 59.99 | J4: PayPal | K4: South | L4: Standard | M4: 45262 | N4: 179.97
A5: TRX0043 | B5: 45400 | C5: CUST046 | D5: Kathleen Bennett | E5: P005 | F5: Blender | G5: Appliances | H5: 3 | I5: 59.99 | J5: Cash | K5: North | L5: Premium | M5: 45114 | N5: 179.97
A6: TRX0212 | B6: 45400 | C6: CUST003 | D6: Michael Brown | E6: P008 | F6: Bookshelf | G6: Furniture | H6: 5 | I6: 149.99 | J6: Credit Card | K6: North | L6: Premium | M6: 45295 | N6: 749.95
A7: TRX0092 | B7: 45403 | C7: CUST024 | D7: Dorothy Nelson | E7: P005 | F7: Blender | G7: Appliances | H7: 2 | I7: 59.99 | J7: Cash | K7: West | L7: Standard | M7: 44746 | N7: 119.98
A8: TRX0193 | B8: 45403 | C8: CUST024 | D8: Dorothy Nelson | E8: P003 | F8: Headphones | G8: Electronics | H8: 5 | I8: 149.99 | J8: Credit Card | K8: Central | L8: Standard | M8: 44418 | N8: 749.95
A9: TRX0240 | B9: 45403 | C9: CUST017 | D9: Charles Allen | E9: P005 | F9: Blender | G9: Appliances | H9: 3 | I9: 59.99 | J9: Debit Card | K9: South | L9: Basic | M9: 45007 | N9: 179.97
A10: TRX0135 | B10: 45405 | C10: CUST009 | D10: Robert Thomas | E10: P001 | F10: Laptop | G10: Electronics | H10: 3 | I10: 899.99 | J10: PayPal | K10: East | L10: Standard | M10: 45299 | N10: 2699.97
A11: TRX0185 | B11: 45408 | C11: CUST026 | D11: Karen Hill | E11: P005 | F11: Blender | G11: Appliances | H11: 3 | I11: 59.99 | J11: Cash | K11: West | L11: Premium | M11: 45207 | N11: 179.97
A12: TRX0138 | B12: 45408 | C12: CUST022 | D12: Susan Green | E12: P008 | F12: Bookshelf | G12: Furniture | H12: 1 | I12: 149.99 | J12: Credit Card | K12: West | L12: Standard | M12: 45103 | N12: 149.99
A13: TRX0209 | B13: 45408 | C13: CUST046 | D13: Kathleen Bennett | E13: P008 | F13: Bookshelf | G13: Furniture | H13: 5 | I13: 149.99 | J13: Debit Card | K13: North | L13: Basic | M13: 44830 | N13: 749.95
... A251: TRX0064 | B251: 45758 | C251: CUST031 | D251: Steven Turner | E251: P010 | F251: Keyboard | G251: Electronics | H251: 3 | I251: 89.99 | J251: Debit Card | K251: North | L251: Premium | M251: 44878 | N251: 269.97

Sheet Lists
A3: Region | B3: Category | C3: Product_ID | D3: Product_Name | E3: Payment_Method | F3: Customer_Segment | G3: Customer_ID | H3: Customer_Name | I3: ALL Region | J3: ALL Category
A4: Central | B4: Appliances | C4: P001 | D4: Laptop | E4: Cash | F4: Basic | G4: CUST001 | H4: {=INDEX(tx_CustName,MATCH(G4,tx_CustID,0))} -> John Smith | I4: All | J4: All
A5: East | B5: Electronics | C5: P002 | D5: Smartphone | E5: Credit Card | F5: Premium | G5: CUST002 | H5: {=INDEX(tx_CustName,MATCH(G5,tx_CustID,0))} -> Emma Wilson | I5: Central | J5: Appliances
A6: North | B6: Furniture | C6: P003 | D6: Headphones | E6: Debit Card | F6: Standard | G6: CUST003 | H6: {=INDEX(tx_CustName,MATCH(G6,tx_CustID,0))} -> Michael Brown | I6: East | J6: Electronics
A7: South | C7: P004 | D7: Coffee Maker | E7: PayPal | G7: CUST004 | H7: {=INDEX(tx_CustName,MATCH(G7,tx_CustID,0))} -> Sarah Davis | I7: North | J7: Furniture
A8: West | C8: P005 | D8: Blender | G8: CUST005 | H8: {=INDEX(tx_CustName,MATCH(G8,tx_CustID,0))} -> James Johnson | I8: South
C9: P006 | D9: Office Chair | G9: CUST006 | H9: {=INDEX(tx_CustName,MATCH(G9,tx_CustID,0))} -> Lisa Anderson | I9: West
C10: P007 | D10: Desk | G10: CUST007 | H10: {=INDEX(tx_CustName,MATCH(G10,tx_CustID,0))} -> David Martinez
C11: P008 | D11: Bookshelf | G11: CUST008 | H11: {=INDEX(tx_CustName,MATCH(G11,tx_CustID,0))} -> Jennifer Taylor
C12: P009 | D12: Monitor | G12: CUST009 | H12: {=INDEX(tx_CustName,MATCH(G12,tx_CustID,0))} -> Robert Thomas
C13: P010 | D13: Keyboard | G13: CUST010 | H13: {=INDEX(tx_CustName,MATCH(G13,tx_CustID,0))} -> Maria Garcia
G14: CUST011 | H14: {=INDEX(tx_CustName,MATCH(G14,tx_CustID,0))} -> William White
G15: CUST012 | H15: {=INDEX(tx_CustName,MATCH(G15,tx_CustID,0))} -> Patricia Moore
G16: CUST013 | H16: {=INDEX(tx_CustName,MATCH(G16,tx_CustID,0))} -> Joseph Jackson
G17: CUST014 | H17: {=INDEX(tx_CustName,MATCH(G17,tx_CustID,0))} -> Linda Martin
G18: CUST015 | H18: {=INDEX(tx_CustName,MATCH(G18,tx_CustID,0))} -> Richard Lee
G19: CUST016 | H19: {=INDEX(tx_CustName,MATCH(G19,tx_CustID,0))} -> Elizabeth Hall
G20: CUST017 | H20: {=INDEX(tx_CustName,MATCH(G20,tx_CustID,0))} -> Charles Allen
G21: CUST018 | H21: {=INDEX(tx_CustName,MATCH(G21,tx_CustID,0))} -> Barbara Young
G22: CUST019 | H22: {=INDEX(tx_CustName,MATCH(G22,tx_CustID,0))} -> Daniel King
G23: CUST020 | H23: {=INDEX(tx_CustName,MATCH(G23,tx_CustID,0))} -> Margaret Wright
G24: CUST021 | H24: {=INDEX(tx_CustName,MATCH(G24,tx_CustID,0))} -> Kevin Scott
G25: CUST022 | H25: {=INDEX(tx_CustName,MATCH(G25,tx_CustID,0))} -> Susan Green
... G53: CUST050 | H53: {=INDEX(tx_CustName,MATCH(G53,tx_CustID,0))} -> Julie Foster

Sheet Date_Time
A1: Live date functions
A2: Item | B2: Result | E2: Customer_ID | F2: Customer_Name | G2: First Purchase | H2: Last Purchase | I2: Customer Since (earliest) | J2: Tenure (full years) | K2: Tenure (extra months) | L2: Days Since Last Purchase | M2: Tenure (text)
A3: TODAY() | B3: =TODAY() -> 46295 | E3: =Lists!G4 -> CUST001 | F3: =Lists!H4 -> John Smith | G3: =MINIFS(tx_Date,tx_CustID,$E3) -> 45740 | H3: =MAXIFS(tx_Date,tx_CustID,$E3) -> 45740 | I3: =MINIFS(tx_Since,tx_CustID,$E3) -> 44560 | J3: =DATEDIF(I3,TODAY(),"Y") -> 4 | K3: =DATEDIF(I3,TODAY(),"YM") -> 9 | L3: =TODAY()-H3 -> 555 | M3: =J3&"y "&K3&"m" -> 4y 9m
A4: NOW() | B4: =NOW() -> 46295.989 | E4: =Lists!G5 -> CUST002 | F4: =Lists!H5 -> Emma Wilson | G4: =MINIFS(tx_Date,tx_CustID,$E4) -> 45430 | H4: =MAXIFS(tx_Date,tx_CustID,$E4) -> 45737 | I4: =MINIFS(tx_Since,tx_CustID,$E4) -> 44748 | J4: =DATEDIF(I4,TODAY(),"Y") -> 4 | K4: =DATEDIF(I4,TODAY(),"YM") -> 2 | L4: =TODAY()-H4 -> 558 | M4: =J4&"y "&K4&"m" -> 4y 2m
A5: First transaction date | B5: =MIN(tx_Date) -> 45393 | E5: =Lists!G6 -> CUST003 | F5: =Lists!H6 -> Michael Brown | G5: =MINIFS(tx_Date,tx_CustID,$E5) -> 45400 | H5: =MAXIFS(tx_Date,tx_CustID,$E5) -> 45707 | I5: =MINIFS(tx_Since,tx_CustID,$E5) -> 44422 | J5: =DATEDIF(I5,TODAY(),"Y") -> 5 | K5: =DATEDIF(I5,TODAY(),"YM") -> 1 | L5: =TODAY()-H5 -> 588 | M5: =J5&"y "&K5&"m" -> 5y 1m
A6: Last transaction date | B6: =MAX(tx_Date) -> 45758 | E6: =Lists!G7 -> CUST004 | F6: =Lists!H7 -> Sarah Davis | G6: =MINIFS(tx_Date,tx_CustID,$E6) -> 45446 | H6: =MAXIFS(tx_Date,tx_CustID,$E6) -> 45619 | I6: =MINIFS(tx_Since,tx_CustID,$E6) -> 44458 | J6: =DATEDIF(I6,TODAY(),"Y") -> 5 | K6: =DATEDIF(I6,TODAY(),"YM") -> 0 | L6: =TODAY()-H6 -> 676 | M6: =J6&"y "&K6&"m" -> 5y 0m
A7: Dataset span (DATEDIF) | B7: =DATEDIF(B5,B6,"M")&" months, "&DATEDIF(B5,B6,"MD")&" days" -> 12 months, 0 days | E7: =Lists!G8 -> CUST005 | F7: =Lists!H8 -> James Johnson | G7: =MINIFS(tx_Date,tx_CustID,$E7) -> 45635 | H7: =MAXIFS(tx_Date,tx_CustID,$E7) -> 45635 | I7: =MINIFS(tx_Since,tx_CustID,$E7) -> 45052 | J7: =DATEDIF(I7,TODAY(),"Y") -> 3 | K7: =DATEDIF(I7,TODAY(),"YM") -> 4 | L7: =TODAY()-H7 -> 660 | M7: =J7&"y "&K7&"m" -> 3y 4m
A8: Days since last transaction | B8: =TODAY()-B6 -> 537 | E8: =Lists!G9 -> CUST006 | F8: =Lists!H9 -> Lisa Anderson | G8: =MINIFS(tx_Date,tx_CustID,$E8) -> 45428 | H8: =MAXIFS(tx_Date,tx_CustID,$E8) -> 45676 | I8: =MINIFS(tx_Since,tx_CustID,$E8) -> 44579 | J8: =DATEDIF(I8,TODAY(),"Y") -> 4 | K8: =DATEDIF(I8,TODAY(),"YM") -> 8 | L8: =TODAY()-H8 -> 619 | M8: =J8&"y "&K8&"m" -> 4y 8m
A9: End of current month (EOMONTH) | B9: =EOMONTH(TODAY(),0) -> 46295 | E9: =Lists!G10 -> CUST007 | F9: =Lists!H10 -> David Martinez | G9: =MINIFS(tx_Date,tx_CustID,$E9) -> 45476 | H9: =MAXIFS(tx_Date,tx_CustID,$E9) -> 45648 | I9: =MINIFS(tx_Since,tx_CustID,$E9) -> 44522 | J9: =DATEDIF(I9,TODAY(),"Y") -> 4 | K9: =DATEDIF(I9,TODAY(),"YM") -> 10 | L9: =TODAY()-H9 -> 647 | M9: =J9&"y "&K9&"m" -> 4y 10m
A10: Days left in current month | B10: =EOMONTH(TODAY(),0)-TODAY() -> 0 | E10: =Lists!G11 -> CUST008 | F10: =Lists!H11 -> Jennifer Taylor | G10: =MINIFS(tx_Date,tx_CustID,$E10) -> 45440 | H10: =MAXIFS(tx_Date,tx_CustID,$E10) -> 45635 | I10: =MINIFS(tx_Since,tx_CustID,$E10) -> 44407 | J10: =DATEDIF(I10,TODAY(),"Y") -> 5 | K10: =DATEDIF(I10,TODAY(),"YM") -> 2 | L10: =TODAY()-H10 -> 660 | M10: =J10&"y "&K10&"m" -> 5y 2m
A11: End of current quarter | B11: =EOMONTH(DATE(YEAR(TODAY()),CEILING(MONTH(TODAY()),3),1),0) -> 46295 | E11: =Lists!G12 -> CUST009 | F11: =Lists!H12 -> Robert Thomas | G11: =MINIFS(tx_Date,tx_CustID,$E11) -> 45405 | H11: =MAXIFS(tx_Date,tx_CustID,$E11) -> 45756 | I11: =MINIFS(tx_Since,tx_CustID,$E11) -> 44395 | J11: =DATEDIF(I11,TODAY(),"Y") -> 5 | K11: =DATEDIF(I11,TODAY(),"YM") -> 2 | L11: =TODAY()-H11 -> 539 | M11: =J11&"y "&K11&"m" -> 5y 2m
A12: Same day next year (EDATE) | B12: =EDATE(TODAY(),12) -> 46660 | E12: =Lists!G13 -> CUST010 | F12: =Lists!H13 -> Maria Garcia | G12: =MINIFS(tx_Date,tx_CustID,$E12) -> 45410 | H12: =MAXIFS(tx_Date,tx_CustID,$E12) -> 45604 | I12: =MINIFS(tx_Since,tx_CustID,$E12) -> 44579 | J12: =DATEDIF(I12,TODAY(),"Y") -> 4 | K12: =DATEDIF(I12,TODAY(),"YM") -> 8 | L12: =TODAY()-H12 -> 691 | M12: =J12&"y "&K12&"m" -> 4y 8m
A13: Last full month in data ends | B13: =EOMONTH(B6,-1) -> 45747 | E13: =Lists!G14 -> CUST011 | F13: =Lists!H14 -> William White | G13: =MINIFS(tx_Date,tx_CustID,$E13) -> 45554 | H13: =MAXIFS(tx_Date,tx_CustID,$E13) -> 45686 | I13: =MINIFS(tx_Since,tx_CustID,$E13) -> 44482 | J13: =DATEDIF(I13,TODAY(),"Y") -> 4 | K13: =DATEDIF(I13,TODAY(),"YM") -> 11 | L13: =TODAY()-H13 -> 609 | M13: =J13&"y "&K13&"m" -> 4y 11m
E14: =Lists!G15 -> CUST012 | F14: =Lists!H15 -> Patricia Moore | G14: =MINIFS(tx_Date,tx_CustID,$E14) -> 45413 | H14: =MAXIFS(tx_Date,tx_CustID,$E14) -> 45607 | I14: =MINIFS(tx_Since,tx_CustID,$E14) -> 44409 | J14: =DATEDIF(I14,TODAY(),"Y") -> 5 | K14: =DATEDIF(I14,TODAY(),"YM") -> 1 | L14: =TODAY()-H14 -> 688 | M14: =J14&"y "&K14&"m" -> 5y 1m
E15: =Lists!G16 -> CUST013 | F15: =Lists!H16 -> Joseph Jackson | G15: =MINIFS(tx_Date,tx_CustID,$E15) -> 45396 | H15: =MAXIFS(tx_Date,tx_CustID,$E15) -> 45627 | I15: =MINIFS(tx_Since,tx_CustID,$E15) -> 44475 | J15: =DATEDIF(I15,TODAY(),"Y") -> 4 | K15: =DATEDIF(I15,TODAY(),"YM") -> 11 | L15: =TODAY()-H15 -> 668 | M15: =J15&"y "&K15&"m" -> 4y 11m
E16: =Lists!G17 -> CUST014 | F16: =Lists!H17 -> Linda Martin | G16: =MINIFS(tx_Date,tx_CustID,$E16) -> 45424 | H16: =MAXIFS(tx_Date,tx_CustID,$E16) -> 45648 | I16: =MINIFS(tx_Since,tx_CustID,$E16) -> 44886 | J16: =DATEDIF(I16,TODAY(),"Y") -> 3 | K16: =DATEDIF(I16,TODAY(),"YM") -> 10 | L16: =TODAY()-H16 -> 647 | M16: =J16&"y "&K16&"m" -> 3y 10m
E17: =Lists!G18 -> CUST015 | F17: =Lists!H18 -> Richard Lee | G17: =MINIFS(tx_Date,tx_CustID,$E17) -> 45564 | H17: =MAXIFS(tx_Date,tx_CustID,$E17) -> 45715 | I17: =MINIFS(tx_Since,tx_CustID,$E17) -> 44728 | J17: =DATEDIF(I17,TODAY(),"Y") -> 4 | K17: =DATEDIF(I17,TODAY(),"YM") -> 3 | L17: =TODAY()-H17 -> 580 | M17: =J17&"y "&K17&"m" -> 4y 3m
E18: =Lists!G19 -> CUST016 | F18: =Lists!H19 -> Elizabeth Hall | G18: =MINIFS(tx_Date,tx_CustID,$E18) -> 45509 | H18: =MAXIFS(tx_Date,tx_CustID,$E18) -> 45711 | I18: =MINIFS(tx_Since,tx_CustID,$E18) -> 44431 | J18: =DATEDIF(I18,TODAY(),"Y") -> 5 | K18: =DATEDIF(I18,TODAY(),"YM") -> 1 | L18: =TODAY()-H18 -> 584 | M18: =J18&"y "&K18&"m" -> 5y 1m
E19: =Lists!G20 -> CUST017 | F19: =Lists!H20 -> Charles Allen | G19: =MINIFS(tx_Date,tx_CustID,$E19) -> 45403 | H19: =MAXIFS(tx_Date,tx_CustID,$E19) -> 45724 | I19: =MINIFS(tx_Since,tx_CustID,$E19) -> 44412 | J19: =DATEDIF(I19,TODAY(),"Y") -> 5 | K19: =DATEDIF(I19,TODAY(),"YM") -> 1 | L19: =TODAY()-H19 -> 571 | M19: =J19&"y "&K19&"m" -> 5y 1m
E20: =Lists!G21 -> CUST018 | F20: =Lists!H21 -> Barbara Young | G20: =MINIFS(tx_Date,tx_CustID,$E20) -> 45412 | H20: =MAXIFS(tx_Date,tx_CustID,$E20) -> 45708 | I20: =MINIFS(tx_Since,tx_CustID,$E20) -> 44613 | J20: =DATEDIF(I20,TODAY(),"Y") -> 4 | K20: =DATEDIF(I20,TODAY(),"YM") -> 7 | L20: =TODAY()-H20 -> 587 | M20: =J20&"y "&K20&"m" -> 4y 7m
E21: =Lists!G22 -> CUST019 | F21: =Lists!H22 -> Daniel King | G21: =MINIFS(tx_Date,tx_CustID,$E21) -> 45443 | H21: =MAXIFS(tx_Date,tx_CustID,$E21) -> 45660 | I21: =MINIFS(tx_Since,tx_CustID,$E21) -> 44446 | J21: =DATEDIF(I21,TODAY(),"Y") -> 5 | K21: =DATEDIF(I21,TODAY(),"YM") -> 0 | L21: =TODAY()-H21 -> 635 | M21: =J21&"y "&K21&"m" -> 5y 0m
E22: =Lists!G23 -> CUST020 | F22: =Lists!H23 -> Margaret Wright | G22: =MINIFS(tx_Date,tx_CustID,$E22) -> 45481 | H22: =MAXIFS(tx_Date,tx_CustID,$E22) -> 45745 | I22: =MINIFS(tx_Since,tx_CustID,$E22) -> 44421 | J22: =DATEDIF(I22,TODAY(),"Y") -> 5 | K22: =DATEDIF(I22,TODAY(),"YM") -> 1 | L22: =TODAY()-H22 -> 550 | M22: =J22&"y "&K22&"m" -> 5y 1m
E23: =Lists!G24 -> CUST021 | F23: =Lists!H24 -> Kevin Scott | G23: =MINIFS(tx_Date,tx_CustID,$E23) -> 45399 | H23: =MAXIFS(tx_Date,tx_CustID,$E23) -> 45704 | I23: =MINIFS(tx_Since,tx_CustID,$E23) -> 44578 | J23: =DATEDIF(I23,TODAY(),"Y") -> 4 | K23: =DATEDIF(I23,TODAY(),"YM") -> 8 | L23: =TODAY()-H23 -> 591 | M23: =J23&"y "&K23&"m" -> 4y 8m
E24: =Lists!G25 -> CUST022 | F24: =Lists!H25 -> Susan Green | G24: =MINIFS(tx_Date,tx_CustID,$E24) -> 45408 | H24: =MAXIFS(tx_Date,tx_CustID,$E24) -> 45682 | I24: =MINIFS(tx_Since,tx_CustID,$E24) -> 44564 | J24: =DATEDIF(I24,TODAY(),"Y") -> 4 | K24: =DATEDIF(I24,TODAY(),"YM") -> 8 | L24: =TODAY()-H24 -> 613 | M24: =J24&"y "&K24&"m" -> 4y 8m
E25: =Lists!G26 -> CUST023 | F25: =Lists!H26 -> Paul Baker | G25: =MINIFS(tx_Date,tx_CustID,$E25) -> 45393 | H25: =MAXIFS(tx_Date,tx_CustID,$E25) -> 45739 | I25: =MINIFS(tx_Since,tx_CustID,$E25) -> 44425 | J25: =DATEDIF(I25,TODAY(),"Y") -> 5 | K25: =DATEDIF(I25,TODAY(),"YM") -> 1 | L25: =TODAY()-H25 -> 556 | M25: =J25&"y "&K25&"m" -> 5y 1m
... E52: =Lists!G53 -> CUST050 | F52: =Lists!H53 -> Julie Foster | G52: =MINIFS(tx_Date,tx_CustID,$E52) -> 45452 | H52: =MAXIFS(tx_Date,tx_CustID,$E52) -> 45452 | I52: =MINIFS(tx_Since,tx_CustID,$E52) -> 44435 | J52: =DATEDIF(I52,TODAY(),"Y") -> 5 | K52: =DATEDIF(I52,TODAY(),"YM") -> 1 | L52: =TODAY()-H52 -> 843 | M52: =J52&"y "&K52&"m" -> 5y 1m

Sheet Customer_Analysis
A3: High-Value percentile | B3: 0.8 | D3: High-Value threshold ($) | E3: =PERCENTILE($E$8:$E$57,B3) -> 6557.8
A4: Mid-Value percentile | B4: 0.5 | D4: Mid-Value threshold ($) | E4: =PERCENTILE($E$8:$E$57,B4) -> 4254.875
N6: Top 10 Customers by Revenue
A7: Customer_ID | B7: Customer_Name | C7: Transactions | D7: Units | E7: Revenue | F7: Avg Order Value | G7: % of Total Revenue | H7: Rank | I7: Tier | J7: Repeat? | K7: Times Name Appears | L7: Last Purchase | N7: Rank | O7: Customer | P7: Revenue | Q7: Share | R7: Transactions | S7: Tier
A8: =Lists!G4 -> CUST001 | B8: =Lists!H4 -> John Smith | C8: =COUNTIF(tx_CustID,$A8) -> 1 | D8: =SUMIF(tx_CustID,$A8,tx_Qty) -> 4 | E8: =SUMIF(tx_CustID,$A8,tx_Total) -> 599.96 | F8: =IF(C8=0,0,E8/C8) -> 599.96 | G8: =E8/$E$58 -> 0.0026177125 | H8: =RANK(E8,$E$8:$E$57,0)+COUNTIF($E$8:E8,E8)-1 -> 47 | I8: =IF(E8>=$E$3,"High-Value",IF(E8>=$E$4,"Mid-Value","Low-Value")) -> Low-Value | J8: =IF(C8>1,"Repeat","One-time") -> One-time | K8: =COUNTIF(tx_CustName,$B8) -> 1 | L8: =MAXIFS(tx_Date,tx_CustID,$A8) -> 45740 | N8: 1 | O8: =INDEX($B$8:$B$57,MATCH($N8,$H$8:$H$57,0)) -> Mark Carter | P8: =INDEX($E$8:$E$57,MATCH($N8,$H$8:$H$57,0)) -> 15659.65 | Q8: =P8/$E$58 -> 0.068325325 | R8: =INDEX($C$8:$C$57,MATCH($N8,$H$8:$H$57,0)) -> 12 | S8: =INDEX($I$8:$I$57,MATCH($N8,$H$8:$H$57,0)) -> High-Value
A9: =Lists!G5 -> CUST002 | B9: =Lists!H5 -> Emma Wilson | C9: =COUNTIF(tx_CustID,$A9) -> 5 | D9: =SUMIF(tx_CustID,$A9,tx_Qty) -> 12 | E9: =SUMIF(tx_CustID,$A9,tx_Total) -> 1229.88 | F9: =IF(C9=0,0,E9/C9) -> 245.976 | G9: =E9/$E$58 -> 0.0053661449 | H9: =RANK(E9,$E$8:$E$57,0)+COUNTIF($E$8:E9,E9)-1 -> 44 | I9: =IF(E9>=$E$3,"High-Value",IF(E9>=$E$4,"Mid-Value","Low-Value")) -> Low-Value | J9: =IF(C9>1,"Repeat","One-time") -> Repeat | K9: =COUNTIF(tx_CustName,$B9) -> 5 | L9: =MAXIFS(tx_Date,tx_CustID,$A9) -> 45737 | N9: 2 | O9: =INDEX($B$8:$B$57,MATCH($N9,$H$8:$H$57,0)) -> Edward Mitchell | P9: =INDEX($E$8:$E$57,MATCH($N9,$H$8:$H$57,0)) -> 11919.77 | Q9: =P9/$E$58 -> 0.052007686 | R9: =INDEX($C$8:$C$57,MATCH($N9,$H$8:$H$57,0)) -> 6 | S9: =INDEX($I$8:$I$57,MATCH($N9,$H$8:$H$57,0)) -> High-Value
A10: =Lists!G6 -> CUST003 | B10: =Lists!H6 -> Michael Brown | C10: =COUNTIF(tx_CustID,$A10) -> 9 | D10: =SUMIF(tx_CustID,$A10,tx_Qty) -> 26 | E10: =SUMIF(tx_CustID,$A10,tx_Total) -> 6169.74 | F10: =IF(C10=0,0,E10/C10) -> 685.52667 | G10: =E10/$E$58 -> 0.026919471 | H10: =RANK(E10,$E$8:$E$57,0)+COUNTIF($E$8:E10,E10)-1 -> 14 | I10: =IF(E10>=$E$3,"High-Value",IF(E10>=$E$4,"Mid-Value","Low-Value")) -> Mid-Value | J10: =IF(C10>1,"Repeat","One-time") -> Repeat | K10: =COUNTIF(tx_CustName,$B10) -> 9 | L10: =MAXIFS(tx_Date,tx_CustID,$A10) -> 45707 | N10: 3 | O10: =INDEX($B$8:$B$57,MATCH($N10,$H$8:$H$57,0)) -> Barbara Young | P10: =INDEX($E$8:$E$57,MATCH($N10,$H$8:$H$57,0)) -> 10649.8 | Q10: =P10/$E$58 -> 0.046466623 | R10: =INDEX($C$8:$C$57,MATCH($N10,$H$8:$H$57,0)) -> 5 | S10: =INDEX($I$8:$I$57,MATCH($N10,$H$8:$H$57,0)) -> High-Value
A11: =Lists!G7 -> CUST004 | B11: =Lists!H7 -> Sarah Davis | C11: =COUNTIF(tx_CustID,$A11) -> 5 | D11: =SUMIF(tx_CustID,$A11,tx_Qty) -> 19 | E11: =SUMIF(tx_CustID,$A11,tx_Total) -> 5499.81 | F11: =IF(C11=0,0,E11/C11) -> 1099.962 | G11: =E11/$E$58 -> 0.023996469 | H11: =RANK(E11,$E$8:$E$57,0)+COUNTIF($E$8:E11,E11)-1 -> 19 | I11: =IF(E11>=$E$3,"High-Value",IF(E11>=$E$4,"Mid-Value","Low-Value")) -> Mid-Value | J11: =IF(C11>1,"Repeat","One-time") -> Repeat | K11: =COUNTIF(tx_CustName,$B11) -> 5 | L11: =MAXIFS(tx_Date,tx_CustID,$A11) -> 45619 | N11: 4 | O11: =INDEX($B$8:$B$57,MATCH($N11,$H$8:$H$57,0)) -> Patricia Moore | P11: =INDEX($E$8:$E$57,MATCH($N11,$H$8:$H$57,0)) -> 9799.73 | Q11: =P11/$E$58 -> 0.042757644 | R11: =INDEX($C$8:$C$57,MATCH($N11,$H$8:$H$57,0)) -> 8 | S11: =INDEX($I$8:$I$57,MATCH($N11,$H$8:$H$57,0)) -> High-Value
A12: =Lists!G8 -> CUST005 | B12: =Lists!H8 -> James Johnson | C12: =COUNTIF(tx_CustID,$A12) -> 1 | D12: =SUMIF(tx_CustID,$A12,tx_Qty) -> 3 | E12: =SUMIF(tx_CustID,$A12,tx_Total) -> 179.97 | F12: =IF(C12=0,0,E12/C12) -> 179.97 | G12: =E12/$E$58 -> 0.00078523522 | H12: =RANK(E12,$E$8:$E$57,0)+COUNTIF($E$8:E12,E12)-1 -> 50 | I12: =IF(E12>=$E$3,"High-Value",IF(E12>=$E$4,"Mid-Value","Low-Value")) -> Low-Value | J12: =IF(C12>1,"Repeat","One-time") -> One-time | K12: =COUNTIF(tx_CustName,$B12) -> 1 | L12: =MAXIFS(tx_Date,tx_CustID,$A12) -> 45635 | N12: 5 | O12: =INDEX($B$8:$B$57,MATCH($N12,$H$8:$H$57,0)) -> Paul Baker | P12: =INDEX($E$8:$E$57,MATCH($N12,$H$8:$H$57,0)) -> 8309.74 | Q12: =P12/$E$58 -> 0.036256601 | R12: =INDEX($C$8:$C$57,MATCH($N12,$H$8:$H$57,0)) -> 8 | S12: =INDEX($I$8:$I$57,MATCH($N12,$H$8:$H$57,0)) -> High-Value
A13: =Lists!G9 -> CUST006 | B13: =Lists!H9 -> Lisa Anderson | C13: =COUNTIF(tx_CustID,$A13) -> 5 | D13: =SUMIF(tx_CustID,$A13,tx_Qty) -> 20 | E13: =SUMIF(tx_CustID,$A13,tx_Total) -> 2039.8 | F13: =IF(C13=0,0,E13/C13) -> 407.96 | G13: =E13/$E$58 -> 0.0088999434 | H13: =RANK(E13,$E$8:$E$57,0)+COUNTIF($E$8:E13,E13)-1 -> 36 | I13: =IF(E13>=$E$3,"High-Value",IF(E13>=$E$4,"Mid-Value","Low-Value")) -> Low-Value | J13: =IF(C13>1,"Repeat","One-time") -> Repeat | K13: =COUNTIF(tx_CustName,$B13) -> 5 | L13: =MAXIFS(tx_Date,tx_CustID,$A13) -> 45676 | N13: 6 | O13: =INDEX($B$8:$B$57,MATCH($N13,$H$8:$H$57,0)) -> Dorothy Nelson | P13: =INDEX($E$8:$E$57,MATCH($N13,$H$8:$H$57,0)) -> 8269.79 | Q13: =P13/$E$58 -> 0.036082294 | R13: =INDEX($C$8:$C$57,MATCH($N13,$H$8:$H$57,0)) -> 6 | S13: =INDEX($I$8:$I$57,MATCH($N13,$H$8:$H$57,0)) -> High-Value
A14: =Lists!G10 -> CUST007 | B14: =Lists!H10 -> David Martinez | C14: =COUNTIF(tx_CustID,$A14) -> 6 | D14: =SUMIF(tx_CustID,$A14,tx_Qty) -> 16 | E14: =SUMIF(tx_CustID,$A14,tx_Total) -> 1809.84 | F14: =IF(C14=0,0,E14/C14) -> 301.64 | G14: =E14/$E$58 -> 0.0078965945 | H14: =RANK(E14,$E$8:$E$57,0)+COUNTIF($E$8:E14,E14)-1 -> 39 | I14: =IF(E14>=$E$3,"High-Value",IF(E14>=$E$4,"Mid-Value","Low-Value")) -> Low-Value | J14: =IF(C14>1,"Repeat","One-time") -> Repeat | K14: =COUNTIF(tx_CustName,$B14) -> 6 | L14: =MAXIFS(tx_Date,tx_CustID,$A14) -> 45648 | N14: 7 | O14: =INDEX($B$8:$B$57,MATCH($N14,$H$8:$H$57,0)) -> Karen Hill | P14: =INDEX($E$8:$E$57,MATCH($N14,$H$8:$H$57,0)) -> 8009.77 | Q14: =P14/$E$58 -> 0.034947789 | R14: =INDEX($C$8:$C$57,MATCH($N14,$H$8:$H$57,0)) -> 8 | S14: =INDEX($I$8:$I$57,MATCH($N14,$H$8:$H$57,0)) -> High-Value
A15: =Lists!G11 -> CUST008 | B15: =Lists!H11 -> Jennifer Taylor | C15: =COUNTIF(tx_CustID,$A15) -> 4 | D15: =SUMIF(tx_CustID,$A15,tx_Qty) -> 15 | E15: =SUMIF(tx_CustID,$A15,tx_Total) -> 4739.85 | F15: =IF(C15=0,0,E15/C15) -> 1184.9625 | G15: =E15/$E$58 -> 0.020680653 | H15: =RANK(E15,$E$8:$E$57,0)+COUNTIF($E$8:E15,E15)-1 -> 24 | I15: =IF(E15>=$E$3,"High-Value",IF(E15>=$E$4,"Mid-Value","Low-Value")) -> Mid-Value | J15: =IF(C15>1,"Repeat","One-time") -> Repeat | K15: =COUNTIF(tx_CustName,$B15) -> 4 | L15: =MAXIFS(tx_Date,tx_CustID,$A15) -> 45635 | N15: 8 | O15: =INDEX($B$8:$B$57,MATCH($N15,$H$8:$H$57,0)) -> Daniel King | P15: =INDEX($E$8:$E$57,MATCH($N15,$H$8:$H$57,0)) -> 7309.8 | Q15: =P15/$E$58 -> 0.031893718 | R15: =INDEX($C$8:$C$57,MATCH($N15,$H$8:$H$57,0)) -> 7 | S15: =INDEX($I$8:$I$57,MATCH($N15,$H$8:$H$57,0)) -> High-Value
A16: =Lists!G12 -> CUST009 | B16: =Lists!H12 -> Robert Thomas | C16: =COUNTIF(tx_CustID,$A16) -> 5 | D16: =SUMIF(tx_CustID,$A16,tx_Qty) -> 10 | E16: =SUMIF(tx_CustID,$A16,tx_Total) -> 3509.9 | F16: =IF(C16=0,0,E16/C16) -> 701.98 | G16: =E16/$E$58 -> 0.015314203 | H16: =RANK(E16,$E$8:$E$57,0)+COUNTIF($E$8:E16,E16)-1 -> 32 | I16: =IF(E16>=$E$3,"High-Value",IF(E16>=$E$4,"Mid-Value","Low-Value")) -> Low-Value | J16: =IF(C16>1,"Repeat","One-time") -> Repeat | K16: =COUNTIF(tx_CustName,$B16) -> 5 | L16: =MAXIFS(tx_Date,tx_CustID,$A16) -> 45756 | N16: 9 | O16: =INDEX($B$8:$B$57,MATCH($N16,$H$8:$H$57,0)) -> Lawrence Reed | P16: =INDEX($E$8:$E$57,MATCH($N16,$H$8:$H$57,0)) -> 6989.77 | Q16: =P16/$E$58 -> 0.030497381 | R16: =INDEX($C$8:$C$57,MATCH($N16,$H$8:$H$57,0)) -> 8 | S16: =INDEX($I$8:$I$57,MATCH($N16,$H$8:$H$57,0)) -> High-Value
A17: =Lists!G13 -> CUST010 | B17: =Lists!H13 -> Maria Garcia | C17: =COUNTIF(tx_CustID,$A17) -> 4 | D17: =SUMIF(tx_CustID,$A17,tx_Qty) -> 7 | E17: =SUMIF(tx_CustID,$A17,tx_Total) -> 1909.93 | F17: =IF(C17=0,0,E17/C17) -> 477.4825 | G17: =E17/$E$58 -> 0.0083333017 | H17: =RANK(E17,$E$8:$E$57,0)+COUNTIF($E$8:E17,E17)-1 -> 38 | I17: =IF(E17>=$E$3,"High-Value",IF(E17>=$E$4,"Mid-Value","Low-Value")) -> Low-Value | J17: =IF(C17>1,"Repeat","One-time") -> Repeat | K17: =COUNTIF(tx_CustName,$B17) -> 4 | L17: =MAXIFS(tx_Date,tx_CustID,$A17) -> 45604 | N17: 10 | O17: =INDEX($B$8:$B$57,MATCH($N17,$H$8:$H$57,0)) -> Joseph Jackson | P17: =INDEX($E$8:$E$57,MATCH($N17,$H$8:$H$57,0)) -> 6949.84 | Q17: =P17/$E$58 -> 0.03032316 | R17: =INDEX($C$8:$C$57,MATCH($N17,$H$8:$H$57,0)) -> 5 | S17: =INDEX($I$8:$I$57,MATCH($N17,$H$8:$H$57,0)) -> High-Value
A18: =Lists!G14 -> CUST011 | B18: =Lists!H14 -> William White | C18: =COUNTIF(tx_CustID,$A18) -> 3 | D18: =SUMIF(tx_CustID,$A18,tx_Qty) -> 9 | E18: =SUMIF(tx_CustID,$A18,tx_Total) -> 4749.91 | F18: =IF(C18=0,0,E18/C18) -> 1583.3033 | G18: =E18/$E$58 -> 0.020724546 | H18: =RANK(E18,$E$8:$E$57,0)+COUNTIF($E$8:E18,E18)-1 -> 23 | I18: =IF(E18>=$E$3,"High-Value",IF(E18>=$E$4,"Mid-Value","Low-Value")) -> Mid-Value | J18: =IF(C18>1,"Repeat","One-time") -> Repeat | K18: =COUNTIF(tx_CustName,$B18) -> 3 | L18: =MAXIFS(tx_Date,tx_CustID,$A18) -> 45686 | O18: Top 10 combined | P18: =SUM(P8:P17) -> 93867.66 | Q18: =SUM(Q8:Q17) -> 0.40955822
A19: =Lists!G15 -> CUST012 | B19: =Lists!H15 -> Patricia Moore | C19: =COUNTIF(tx_CustID,$A19) -> 8 | D19: =SUMIF(tx_CustID,$A19,tx_Qty) -> 27 | E19: =SUMIF(tx_CustID,$A19,tx_Total) -> 9799.73 | F19: =IF(C19=0,0,E19/C19) -> 1224.9662 | G19: =E19/$E$58 -> 0.042757644 | H19: =RANK(E19,$E$8:$E$57,0)+COUNTIF($E$8:E19,E19)-1 -> 4 | I19: =IF(E19>=$E$3,"High-Value",IF(E19>=$E$4,"Mid-Value","Low-Value")) -> High-Value | J19: =IF(C19>1,"Repeat","One-time") -> Repeat | K19: =COUNTIF(tx_CustName,$B19) -> 8 | L19: =MAXIFS(tx_Date,tx_CustID,$A19) -> 45607
A20: =Lists!G16 -> CUST013 | B20: =Lists!H16 -> Joseph Jackson | C20: =COUNTIF(tx_CustID,$A20) -> 5 | D20: =SUMIF(tx_CustID,$A20,tx_Qty) -> 16 | E20: =SUMIF(tx_CustID,$A20,tx_Total) -> 6949.84 | F20: =IF(C20=0,0,E20/C20) -> 1389.968 | G20: =E20/$E$58 -> 0.03032316 | H20: =RANK(E20,$E$8:$E$57,0)+COUNTIF($E$8:E20,E20)-1 -> 10 | I20: =IF(E20>=$E$3,"High-Value",IF(E20>=$E$4,"Mid-Value","Low-Value")) -> High-Value | J20: =IF(C20>1,"Repeat","One-time") -> Repeat | K20: =COUNTIF(tx_CustName,$B20) -> 5 | L20: =MAXIFS(tx_Date,tx_CustID,$A20) -> 45627
A21: =Lists!G17 -> CUST014 | B21: =Lists!H17 -> Linda Martin | C21: =COUNTIF(tx_CustID,$A21) -> 4 | D21: =SUMIF(tx_CustID,$A21,tx_Qty) -> 10 | E21: =SUMIF(tx_CustID,$A21,tx_Total) -> 1289.9 | F21: =IF(C21=0,0,E21/C21) -> 322.475 | G21: =E21/$E$58 -> 0.0056280209 | H21: =RANK(E21,$E$8:$E$57,0)+COUNTIF($E$8:E21,E21)-1 -> 43 | I21: =IF(E21>=$E$3,"High-Value",IF(E21>=$E$4,"Mid-Value","Low-Value")) -> Low-Value | J21: =IF(C21>1,"Repeat","One-time") -> Repeat | K21: =COUNTIF(tx_CustName,$B21) -> 4 | L21: =MAXIFS(tx_Date,tx_CustID,$A21) -> 45648 | N21: Repeat customers | Q21: =COUNTIF(J8:J57,"Repeat") -> 47
A22: =Lists!G18 -> CUST015 | B22: =Lists!H18 -> Richard Lee | C22: =COUNTIF(tx_CustID,$A22) -> 3 | D22: =SUMIF(tx_CustID,$A22,tx_Qty) -> 7 | E22: =SUMIF(tx_CustID,$A22,tx_Total) -> 739.93 | F22: =IF(C22=0,0,E22/C22) -> 246.64333 | G22: =E22/$E$58 -> 0.0032284219 | H22: =RANK(E22,$E$8:$E$57,0)+COUNTIF($E$8:E22,E22)-1 -> 46 | I22: =IF(E22>=$E$3,"High-Value",IF(E22>=$E$4,"Mid-Value","Low-Value")) -> Low-Value | J22: =IF(C22>1,"Repeat","One-time") -> Repeat | K22: =COUNTIF(tx_CustName,$B22) -> 3 | L22: =MAXIFS(tx_Date,tx_CustID,$A22) -> 45715 | N22: Average revenue per customer | Q22: =E58/COUNTIF(C8:C57,">0") -> 4583.8494
A23: =Lists!G19 -> CUST016 | B23: =Lists!H19 -> Elizabeth Hall | C23: =COUNTIF(tx_CustID,$A23) -> 4 | D23: =SUMIF(tx_CustID,$A23,tx_Qty) -> 14 | E23: =SUMIF(tx_CustID,$A23,tx_Total) -> 3649.86 | F23: =IF(C23=0,0,E23/C23) -> 912.465 | G23: =E23/$E$58 -> 0.015924869 | H23: =RANK(E23,$E$8:$E$57,0)+COUNTIF($E$8:E23,E23)-1 -> 31 | I23: =IF(E23>=$E$3,"High-Value",IF(E23>=$E$4,"Mid-Value","Low-Value")) -> Low-Value | J23: =IF(C23>1,"Repeat","One-time") -> Repeat | K23: =COUNTIF(tx_CustName,$B23) -> 4 | L23: =MAXIFS(tx_Date,tx_CustID,$A23) -> 45711
A24: =Lists!G20 -> CUST017 | B24: =Lists!H20 -> Charles Allen | C24: =COUNTIF(tx_CustID,$A24) -> 9 | D24: =SUMIF(tx_CustID,$A24,tx_Qty) -> 27 | E24: =SUMIF(tx_CustID,$A24,tx_Total) -> 5089.73 | F24: =IF(C24=0,0,E24/C24) -> 565.52556 | G24: =E24/$E$58 -> 0.02220723 | H24: =RANK(E24,$E$8:$E$57,0)+COUNTIF($E$8:E24,E24)-1 -> 20 | I24: =IF(E24>=$E$3,"High-Value",IF(E24>=$E$4,"Mid-Value","Low-Value")) -> Mid-Value | J24: =IF(C24>1,"Repeat","One-time") -> Repeat | K24: =COUNTIF(tx_CustName,$B24) -> 9 | L24: =MAXIFS(tx_Date,tx_CustID,$A24) -> 45724
A25: =Lists!G21 -> CUST018 | B25: =Lists!H21 -> Barbara Young | C25: =COUNTIF(tx_CustID,$A25) -> 5 | D25: =SUMIF(tx_CustID,$A25,tx_Qty) -> 20 | E25: =SUMIF(tx_CustID,$A25,tx_Total) -> 10649.8 | F25: =IF(C25=0,0,E25/C25) -> 2129.96 | G25: =E25/$E$58 -> 0.046466623 | H25: =RANK(E25,$E$8:$E$57,0)+COUNTIF($E$8:E25,E25)-1 -> 3 | I25: =IF(E25>=$E$3,"High-Value",IF(E25>=$E$4,"Mid-Value","Low-Value")) -> High-Value | J25: =IF(C25>1,"Repeat","One-time") -> Repeat | K25: =COUNTIF(tx_CustName,$B25) -> 5 | L25: =MAXIFS(tx_Date,tx_CustID,$A25) -> 45708
A26: =Lists!G22 -> CUST019 | B26: =Lists!H22 -> Daniel King | C26: =COUNTIF(tx_CustID,$A26) -> 7 | D26: =SUMIF(tx_CustID,$A26,tx_Qty) -> 20 | E26: =SUMIF(tx_CustID,$A26,tx_Total) -> 7309.8 | F26: =IF(C26=0,0,E26/C26) -> 1044.2571 | G26: =E26/$E$58 -> 0.031893718 | H26: =RANK(E26,$E$8:$E$57,0)+COUNTIF($E$8:E26,E26)-1 -> 8 | I26: =IF(E26>=$E$3,"High-Value",IF(E26>=$E$4,"Mid-Value","Low-Value")) -> High-Value | J26: =IF(C26>1,"Repeat","One-time") -> Repeat | K26: =COUNTIF(tx_CustName,$B26) -> 7 | L26: =MAXIFS(tx_Date,tx_CustID,$A26) -> 45660
A27: =Lists!G23 -> CUST020 | B27: =Lists!H23 -> Margaret Wright | C27: =COUNTIF(tx_CustID,$A27) -> 4 | D27: =SUMIF(tx_CustID,$A27,tx_Qty) -> 12 | E27: =SUMIF(tx_CustID,$A27,tx_Total) -> 2099.88 | F27: =IF(C27=0,0,E27/C27) -> 524.97 | G27: =E27/$E$58 -> 0.0091620811 | H27: =RANK(E27,$E$8:$E$57,0)+COUNTIF($E$8:E27,E27)-1 -> 35 | I27: =IF(E27>=$E$3,"High-Value",IF(E27>=$E$4,"Mid-Value","Low-Value")) -> Low-Value | J27: =IF(C27>1,"Repeat","One-time") -> Repeat | K27: =COUNTIF(tx_CustName,$B27) -> 4 | L27: =MAXIFS(tx_Date,tx_CustID,$A27) -> 45745
A28: =Lists!G24 -> CUST021 | B28: =Lists!H24 -> Kevin Scott | C28: =COUNTIF(tx_CustID,$A28) -> 6 | D28: =SUMIF(tx_CustID,$A28,tx_Qty) -> 13 | E28: =SUMIF(tx_CustID,$A28,tx_Total) -> 3259.87 | F28: =IF(C28=0,0,E28/C28) -> 543.31167 | G28: =E28/$E$58 -> 0.014223286 | H28: =RANK(E28,$E$8:$E$57,0)+COUNTIF($E$8:E28,E28)-1 -> 33 | I28: =IF(E28>=$E$3,"High-Value",IF(E28>=$E$4,"Mid-Value","Low-Value")) -> Low-Value | J28: =IF(C28>1,"Repeat","One-time") -> Repeat | K28: =COUNTIF(tx_CustName,$B28) -> 6 | L28: =MAXIFS(tx_Date,tx_CustID,$A28) -> 45704
A29: =Lists!G25 -> CUST022 | B29: =Lists!H25 -> Susan Green | C29: =COUNTIF(tx_CustID,$A29) -> 4 | D29: =SUMIF(tx_CustID,$A29,tx_Qty) -> 11 | E29: =SUMIF(tx_CustID,$A29,tx_Total) -> 1979.89 | F29: =IF(C29=0,0,E29/C29) -> 494.9725 | G29: =E29/$E$58 -> 0.0086385473 | H29: =RANK(E29,$E$8:$E$57,0)+COUNTIF($E$8:E29,E29)-1 -> 37 | I29: =IF(E29>=$E$3,"High-Value",IF(E29>=$E$4,"Mid-Value","Low-Value")) -> Low-Value | J29: =IF(C29>1,"Repeat","One-time") -> Repeat | K29: =COUNTIF(tx_CustName,$B29) -> 4 | L29: =MAXIFS(tx_Date,tx_CustID,$A29) -> 45682
A30: =Lists!G26 -> CUST023 | B30: =Lists!H26 -> Paul Baker | C30: =COUNTIF(tx_CustID,$A30) -> 8 | D30: =SUMIF(tx_CustID,$A30,tx_Qty) -> 26 | E30: =SUMIF(tx_CustID,$A30,tx_Total) -> 8309.74 | F30: =IF(C30=0,0,E30/C30) -> 1038.7175 | G30: =E30/$E$58 -> 0.036256601 | H30: =RANK(E30,$E$8:$E$57,0)+COUNTIF($E$8:E30,E30)-1 -> 5 | I30: =IF(E30>=$E$3,"High-Value",IF(E30>=$E$4,"Mid-Value","Low-Value")) -> High-Value | J30: =IF(C30>1,"Repeat","One-time") -> Repeat | K30: =COUNTIF(tx_CustName,$B30) -> 8 | L30: =MAXIFS(tx_Date,tx_CustID,$A30) -> 45739
A31: =Lists!G27 -> CUST024 | B31: =Lists!H27 -> Dorothy Nelson | C31: =COUNTIF(tx_CustID,$A31) -> 6 | D31: =SUMIF(tx_CustID,$A31,tx_Qty) -> 21 | E31: =SUMIF(tx_CustID,$A31,tx_Total) -> 8269.79 | F31: =IF(C31=0,0,E31/C31) -> 1378.2983 | G31: =E31/$E$58 -> 0.036082294 | H31: =RANK(E31,$E$8:$E$57,0)+COUNTIF($E$8:E31,E31)-1 -> 6 | I31: =IF(E31>=$E$3,"High-Value",IF(E31>=$E$4,"Mid-Value","Low-Value")) -> High-Value | J31: =IF(C31>1,"Repeat","One-time") -> Repeat | K31: =COUNTIF(tx_CustName,$B31) -> 6 | L31: =MAXIFS(tx_Date,tx_CustID,$A31) -> 45737
A32: =Lists!G28 -> CUST025 | B32: =Lists!H28 -> Mark Carter | C32: =COUNTIF(tx_CustID,$A32) -> 12 | D32: =SUMIF(tx_CustID,$A32,tx_Qty) -> 35 | E32: =SUMIF(tx_CustID,$A32,tx_Total) -> 15659.65 | F32: =IF(C32=0,0,E32/C32) -> 1304.9708 | G32: =E32/$E$58 -> 0.068325325 | H32: =RANK(E32,$E$8:$E$57,0)+COUNTIF($E$8:E32,E32)-1 -> 1 | I32: =IF(E32>=$E$3,"High-Value",IF(E32>=$E$4,"Mid-Value","Low-Value")) -> High-Value | J32: =IF(C32>1,"Repeat","One-time") -> Repeat | K32: =COUNTIF(tx_CustName,$B32) -> 12 | L32: =MAXIFS(tx_Date,tx_CustID,$A32) -> 45686
A33: =Lists!G29 -> CUST026 | B33: =Lists!H29 -> Karen Hill | C33: =COUNTIF(tx_CustID,$A33) -> 8 | D33: =SUMIF(tx_CustID,$A33,tx_Qty) -> 23 | E33: =SUMIF(tx_CustID,$A33,tx_Total) -> 8009.77 | F33: =IF(C33=0,0,E33/C33) -> 1001.2213 | G33: =E33/$E$58 -> 0.034947789 | H33: =RANK(E33,$E$8:$E$57,0)+COUNTIF($E$8:E33,E33)-1 -> 7 | I33: =IF(E33>=$E$3,"High-Value",IF(E33>=$E$4,"Mid-Value","Low-Value")) -> High-Value | J33: =IF(C33>1,"Repeat","One-time") -> Repeat | K33: =COUNTIF(tx_CustName,$B33) -> 8 | L33: =MAXIFS(tx_Date,tx_CustID,$A33) -> 45746
A34: =Lists!G30 -> CUST027 | B34: =Lists!H30 -> George Adams | C34: =COUNTIF(tx_CustID,$A34) -> 3 | D34: =SUMIF(tx_CustID,$A34,tx_Qty) -> 7 | E34: =SUMIF(tx_CustID,$A34,tx_Total) -> 3779.93 | F34: =IF(C34=0,0,E34/C34) -> 1259.9767 | G34: =E34/$E$58 -> 0.016492383 | H34: =RANK(E34,$E$8:$E$57,0)+COUNTIF($E$8:E34,E34)-1 -> 28 | I34: =IF(E34>=$E$3,"High-Value",IF(E34>=$E$4,"Mid-Value","Low-Value")) -> Low-Value | J34: =IF(C34>1,"Repeat","One-time") -> Repeat | K34: =COUNTIF(tx_CustName,$B34) -> 3 | L34: =MAXIFS(tx_Date,tx_CustID,$A34) -> 45608
... A57: =Lists!G53 -> CUST050 | B57: =Lists!H53 -> Julie Foster | C57: =COUNTIF(tx_CustID,$A57) -> 1 | D57: =SUMIF(tx_CustID,$A57,tx_Qty) -> 4 | E57: =SUMIF(tx_CustID,$A57,tx_Total) -> 239.96 | F57: =IF(C57=0,0,E57/C57) -> 239.96 | G57: =E57/$E$58 -> 0.0010469803 | H57: =RANK(E57,$E$8:$E$57,0)+COUNTIF($E$8:E57,E57)-1 -> 49 | I57: =IF(E57>=$E$3,"High-Value",IF(E57>=$E$4,"Mid-Value","Low-Value")) -> Low-Value | J57: =IF(C57>1,"Repeat","One-time") -> One-time | K57: =COUNTIF(tx_CustName,$B57) -> 1 | L57: =MAXIFS(tx_Date,tx_CustID,$A57) -> 45452
A58: Total | C58: =SUM(C8:C57) -> 250 | D58: =SUM(D8:D57) -> 753 | E58: =SUM(E8:E57) -> 229192.47 | F58: =E58/C58 -> 916.76988 | G58: =SUM(G8:G57) -> 1

Sheet Product_Analysis
M4: Most Sold Products
A5: Product_ID | B5: Product | C5: Category | D5: List Price | E5: Times Purchased | F5: Units Sold | G5: Revenue | H5: Revenue Share | I5: Rank as per Frequency | J5: Rank as per Units | K5: Rank as per Revenue | M5: Rank | N5: Product | O5: Units | P5: Revenue | Q5: Times Purchased
A6: =Lists!C4 -> P001 | B6: =Lists!D4 -> Laptop | C6: {=INDEX(tx_Category,MATCH($B6,tx_Product,0))} -> Electronics | D6: {=INDEX(tx_Price,MATCH($B6,tx_Product,0))} -> 899.99 | E6: =COUNTIF(tx_Product,$B6) -> 24 | F6: =SUMIF(tx_Product,$B6,tx_Qty) -> 75 | G6: =SUMIF(tx_Product,$B6,tx_Total) -> 67499.25 | H6: =G6/$G$16 -> 0.29450902 | I6: =RANK(E6,$E$6:$E$15,0)+COUNTIF($E$6:E6,E6)-1 -> 7 | J6: =RANK(F6,$F$6:$F$15,0)+COUNTIF($F$6:F6,F6)-1 -> 7 | K6: =RANK(G6,$G$6:$G$15,0)+COUNTIF($G$6:G6,G6)-1 -> 1 | M6: 1 | N6: =INDEX($B$6:$B$15,MATCH($M6,$J$6:$J$15,0)) -> Bookshelf | O6: =INDEX($F$6:$F$15,MATCH($M6,$J$6:$J$15,0)) -> 102 | P6: =INDEX($G$6:$G$15,MATCH($M6,$J$6:$J$15,0)) -> 15298.98 | Q6: =INDEX($E$6:$E$15,MATCH($M6,$J$6:$J$15,0)) -> 35
A7: =Lists!C5 -> P002 | B7: =Lists!D5 -> Smartphone | C7: {=INDEX(tx_Category,MATCH($B7,tx_Product,0))} -> Electronics | D7: {=INDEX(tx_Price,MATCH($B7,tx_Product,0))} -> 699.99 | E7: =COUNTIF(tx_Product,$B7) -> 31 | F7: =SUMIF(tx_Product,$B7,tx_Qty) -> 96 | G7: =SUMIF(tx_Product,$B7,tx_Total) -> 67199.04 | H7: =G7/$G$16 -> 0.29319916 | I7: =RANK(E7,$E$6:$E$15,0)+COUNTIF($E$6:E7,E7)-1 -> 3 | J7: =RANK(F7,$F$6:$F$15,0)+COUNTIF($F$6:F7,F7)-1 -> 2 | K7: =RANK(G7,$G$6:$G$15,0)+COUNTIF($G$6:G7,G7)-1 -> 2 | M7: 2 | N7: =INDEX($B$6:$B$15,MATCH($M7,$J$6:$J$15,0)) -> Smartphone | O7: =INDEX($F$6:$F$15,MATCH($M7,$J$6:$J$15,0)) -> 96 | P7: =INDEX($G$6:$G$15,MATCH($M7,$J$6:$J$15,0)) -> 67199.04 | Q7: =INDEX($E$6:$E$15,MATCH($M7,$J$6:$J$15,0)) -> 31
A8: =Lists!C6 -> P003 | B8: =Lists!D6 -> Headphones | C8: {=INDEX(tx_Category,MATCH($B8,tx_Product,0))} -> Electronics | D8: {=INDEX(tx_Price,MATCH($B8,tx_Product,0))} -> 149.99 | E8: =COUNTIF(tx_Product,$B8) -> 16 | F8: =SUMIF(tx_Product,$B8,tx_Qty) -> 47 | G8: =SUMIF(tx_Product,$B8,tx_Total) -> 7049.53 | H8: =G8/$G$16 -> 0.030758122 | I8: =RANK(E8,$E$6:$E$15,0)+COUNTIF($E$6:E8,E8)-1 -> 8 | J8: =RANK(F8,$F$6:$F$15,0)+COUNTIF($F$6:F8,F8)-1 -> 9 | K8: =RANK(G8,$G$6:$G$15,0)+COUNTIF($G$6:G8,G8)-1 -> 8 | M8: 3 | N8: =INDEX($B$6:$B$15,MATCH($M8,$J$6:$J$15,0)) -> Keyboard | O8: =INDEX($F$6:$F$15,MATCH($M8,$J$6:$J$15,0)) -> 89 | P8: =INDEX($G$6:$G$15,MATCH($M8,$J$6:$J$15,0)) -> 8009.11 | Q8: =INDEX($E$6:$E$15,MATCH($M8,$J$6:$J$15,0)) -> 34
A9: =Lists!C7 -> P004 | B9: =Lists!D7 -> Coffee Maker | C9: {=INDEX(tx_Category,MATCH($B9,tx_Product,0))} -> Appliances | D9: {=INDEX(tx_Price,MATCH($B9,tx_Product,0))} -> 79.99 | E9: =COUNTIF(tx_Product,$B9) -> 14 | F9: =SUMIF(tx_Product,$B9,tx_Qty) -> 39 | G9: =SUMIF(tx_Product,$B9,tx_Total) -> 3119.61 | H9: =G9/$G$16 -> 0.013611311 | I9: =RANK(E9,$E$6:$E$15,0)+COUNTIF($E$6:E9,E9)-1 -> 10 | J9: =RANK(F9,$F$6:$F$15,0)+COUNTIF($F$6:F9,F9)-1 -> 10 | K9: =RANK(G9,$G$6:$G$15,0)+COUNTIF($G$6:G9,G9)-1 -> 10 | M9: 4 | N9: =INDEX($B$6:$B$15,MATCH($M9,$J$6:$J$15,0)) -> Monitor | O9: =INDEX($F$6:$F$15,MATCH($M9,$J$6:$J$15,0)) -> 88 | P9: =INDEX($G$6:$G$15,MATCH($M9,$J$6:$J$15,0)) -> 21999.12 | Q9: =INDEX($E$6:$E$15,MATCH($M9,$J$6:$J$15,0)) -> 26
A10: =Lists!C8 -> P005 | B10: =Lists!D8 -> Blender | C10: {=INDEX(tx_Category,MATCH($B10,tx_Product,0))} -> Appliances | D10: {=INDEX(tx_Price,MATCH($B10,tx_Product,0))} -> 59.99 | E10: =COUNTIF(tx_Product,$B10) -> 29 | F10: =SUMIF(tx_Product,$B10,tx_Qty) -> 87 | G10: =SUMIF(tx_Product,$B10,tx_Total) -> 5219.13 | H10: =G10/$G$16 -> 0.022771821 | I10: =RANK(E10,$E$6:$E$15,0)+COUNTIF($E$6:E10,E10)-1 -> 4 | J10: =RANK(F10,$F$6:$F$15,0)+COUNTIF($F$6:F10,F10)-1 -> 5 | K10: =RANK(G10,$G$6:$G$15,0)+COUNTIF($G$6:G10,G10)-1 -> 9 | M10: 5 | N10: =INDEX($B$6:$B$15,MATCH($M10,$J$6:$J$15,0)) -> Blender | O10: =INDEX($F$6:$F$15,MATCH($M10,$J$6:$J$15,0)) -> 87 | P10: =INDEX($G$6:$G$15,MATCH($M10,$J$6:$J$15,0)) -> 5219.13 | Q10: =INDEX($E$6:$E$15,MATCH($M10,$J$6:$J$15,0)) -> 29
A11: =Lists!C9 -> P006 | B11: =Lists!D9 -> Office Chair | C11: {=INDEX(tx_Category,MATCH($B11,tx_Product,0))} -> Furniture | D11: {=INDEX(tx_Price,MATCH($B11,tx_Product,0))} -> 199.99 | E11: =COUNTIF(tx_Product,$B11) -> 15 | F11: =SUMIF(tx_Product,$B11,tx_Qty) -> 52 | G11: =SUMIF(tx_Product,$B11,tx_Total) -> 10399.48 | H11: =G11/$G$16 -> 0.04537444 | I11: =RANK(E11,$E$6:$E$15,0)+COUNTIF($E$6:E11,E11)-1 -> 9 | J11: =RANK(F11,$F$6:$F$15,0)+COUNTIF($F$6:F11,F11)-1 -> 8 | K11: =RANK(G11,$G$6:$G$15,0)+COUNTIF($G$6:G11,G11)-1 -> 6 | M11: 6 | N11: =INDEX($B$6:$B$15,MATCH($M11,$J$6:$J$15,0)) -> Desk | O11: =INDEX($F$6:$F$15,MATCH($M11,$J$6:$J$15,0)) -> 78 | P11: =INDEX($G$6:$G$15,MATCH($M11,$J$6:$J$15,0)) -> 23399.22 | Q11: =INDEX($E$6:$E$15,MATCH($M11,$J$6:$J$15,0)) -> 26
A12: =Lists!C10 -> P007 | B12: =Lists!D10 -> Desk | C12: {=INDEX(tx_Category,MATCH($B12,tx_Product,0))} -> Furniture | D12: {=INDEX(tx_Price,MATCH($B12,tx_Product,0))} -> 299.99 | E12: =COUNTIF(tx_Product,$B12) -> 26 | F12: =SUMIF(tx_Product,$B12,tx_Qty) -> 78 | G12: =SUMIF(tx_Product,$B12,tx_Total) -> 23399.22 | H12: =G12/$G$16 -> 0.10209419 | I12: =RANK(E12,$E$6:$E$15,0)+COUNTIF($E$6:E12,E12)-1 -> 5 | J12: =RANK(F12,$F$6:$F$15,0)+COUNTIF($F$6:F12,F12)-1 -> 6 | K12: =RANK(G12,$G$6:$G$15,0)+COUNTIF($G$6:G12,G12)-1 -> 3 | M12: 7 | N12: =INDEX($B$6:$B$15,MATCH($M12,$J$6:$J$15,0)) -> Laptop | O12: =INDEX($F$6:$F$15,MATCH($M12,$J$6:$J$15,0)) -> 75 | P12: =INDEX($G$6:$G$15,MATCH($M12,$J$6:$J$15,0)) -> 67499.25 | Q12: =INDEX($E$6:$E$15,MATCH($M12,$J$6:$J$15,0)) -> 24
A13: =Lists!C11 -> P008 | B13: =Lists!D11 -> Bookshelf | C13: {=INDEX(tx_Category,MATCH($B13,tx_Product,0))} -> Furniture | D13: {=INDEX(tx_Price,MATCH($B13,tx_Product,0))} -> 149.99 | E13: =COUNTIF(tx_Product,$B13) -> 35 | F13: =SUMIF(tx_Product,$B13,tx_Qty) -> 102 | G13: =SUMIF(tx_Product,$B13,tx_Total) -> 15298.98 | H13: =G13/$G$16 -> 0.066751669 | I13: =RANK(E13,$E$6:$E$15,0)+COUNTIF($E$6:E13,E13)-1 -> 1 | J13: =RANK(F13,$F$6:$F$15,0)+COUNTIF($F$6:F13,F13)-1 -> 1 | K13: =RANK(G13,$G$6:$G$15,0)+COUNTIF($G$6:G13,G13)-1 -> 5 | M13: 8 | N13: =INDEX($B$6:$B$15,MATCH($M13,$J$6:$J$15,0)) -> Office Chair | O13: =INDEX($F$6:$F$15,MATCH($M13,$J$6:$J$15,0)) -> 52 | P13: =INDEX($G$6:$G$15,MATCH($M13,$J$6:$J$15,0)) -> 10399.48 | Q13: =INDEX($E$6:$E$15,MATCH($M13,$J$6:$J$15,0)) -> 15
A14: =Lists!C12 -> P009 | B14: =Lists!D12 -> Monitor | C14: {=INDEX(tx_Category,MATCH($B14,tx_Product,0))} -> Electronics | D14: {=INDEX(tx_Price,MATCH($B14,tx_Product,0))} -> 249.99 | E14: =COUNTIF(tx_Product,$B14) -> 26 | F14: =SUMIF(tx_Product,$B14,tx_Qty) -> 88 | G14: =SUMIF(tx_Product,$B14,tx_Total) -> 21999.12 | H14: =G14/$G$16 -> 0.095985352 | I14: =RANK(E14,$E$6:$E$15,0)+COUNTIF($E$6:E14,E14)-1 -> 6 | J14: =RANK(F14,$F$6:$F$15,0)+COUNTIF($F$6:F14,F14)-1 -> 4 | K14: =RANK(G14,$G$6:$G$15,0)+COUNTIF($G$6:G14,G14)-1 -> 4 | M14: 9 | N14: =INDEX($B$6:$B$15,MATCH($M14,$J$6:$J$15,0)) -> Headphones | O14: =INDEX($F$6:$F$15,MATCH($M14,$J$6:$J$15,0)) -> 47 | P14: =INDEX($G$6:$G$15,MATCH($M14,$J$6:$J$15,0)) -> 7049.53 | Q14: =INDEX($E$6:$E$15,MATCH($M14,$J$6:$J$15,0)) -> 16
A15: =Lists!C13 -> P010 | B15: =Lists!D13 -> Keyboard | C15: {=INDEX(tx_Category,MATCH($B15,tx_Product,0))} -> Electronics | D15: {=INDEX(tx_Price,MATCH($B15,tx_Product,0))} -> 89.99 | E15: =COUNTIF(tx_Product,$B15) -> 34 | F15: =SUMIF(tx_Product,$B15,tx_Qty) -> 89 | G15: =SUMIF(tx_Product,$B15,tx_Total) -> 8009.11 | H15: =G15/$G$16 -> 0.034944909 | I15: =RANK(E15,$E$6:$E$15,0)+COUNTIF($E$6:E15,E15)-1 -> 2 | J15: =RANK(F15,$F$6:$F$15,0)+COUNTIF($F$6:F15,F15)-1 -> 3 | K15: =RANK(G15,$G$6:$G$15,0)+COUNTIF($G$6:G15,G15)-1 -> 7 | M15: 10 | N15: =INDEX($B$6:$B$15,MATCH($M15,$J$6:$J$15,0)) -> Coffee Maker | O15: =INDEX($F$6:$F$15,MATCH($M15,$J$6:$J$15,0)) -> 39 | P15: =INDEX($G$6:$G$15,MATCH($M15,$J$6:$J$15,0)) -> 3119.61 | Q15: =INDEX($E$6:$E$15,MATCH($M15,$J$6:$J$15,0)) -> 14
A16: Total | E16: =SUM(E6:E15) -> 250 | F16: =SUM(F6:F15) -> 753 | G16: =SUM(G6:G15) -> 229192.47 | H16: =SUM(H6:H15) -> 1
A19: Most frequently purchased | B19: {=INDEX($B$6:$B$15,MATCH(1,$I$6:$I$15,0))} -> Bookshelf | C19: =MAX($E$6:$E$15) -> 35
A20: Most units sold | B20: {=INDEX($B$6:$B$15,MATCH(1,$J$6:$J$15,0))} -> Bookshelf | C20: =MAX($F$6:$F$15) -> 102
A21: Highest revenue product | B21: {=INDEX($B$6:$B$15,MATCH(1,$K$6:$K$15,0))} -> Laptop | C21: =MAX($G$6:$G$15) -> 67499.25
A22: Least frequently purchased product | B22: {=INDEX($B$6:$B$15,MATCH(10,$I$6:$I$15,0))} -> Coffee Maker | C22: =MIN($E$6:$E$15) -> 14

Sheet Pivot_Summaries
A3: Revenue by Region and Category | J3: Monthly trend
A4: Region | B4: =Lists!B4 -> Appliances | C4: =Lists!B5 -> Electronics | D4: =Lists!B6 -> Furniture | E4: Total | J4: Month Start | K4: Month End | L4: Revenue | M4: Transactions | N4: Units | O4: MoM | P4: Coverage | Q4: Label
A5: =Lists!A4 -> Central | B5: =SUMIFS(tx_Total,tx_Region,$A5,tx_Category,B$4) -> 1999.71 | C5: =SUMIFS(tx_Total,tx_Region,$A5,tx_Category,C$4) -> 24889.33 | D5: =SUMIFS(tx_Total,tx_Region,$A5,tx_Category,D$4) -> 14399.3 | E5: =SUM(B5:D5) -> 41288.34 | J5: =DATE(YEAR(MIN(tx_Date)),MONTH(MIN(tx_Date)),1) -> 45383 | K5: =EOMONTH(J5,0) -> 45412 | L5: =SUMIFS(tx_Total,tx_Date,">="&J5,tx_Date,"<="&K5) -> 20919.33 | M5: =COUNTIFS(tx_Date,">="&J5,tx_Date,"<="&K5) -> 21 | N5: =SUMIFS(tx_Qty,tx_Date,">="&J5,tx_Date,"<="&K5) -> 67 | P5: =IF(AND(MIN(tx_Date)<=J5,MAX(tx_Date)>=K5),"Full","Partial") -> Partial | Q5: =TEXT(J5,"mmm-yy") -> Apr-24
A6: =Lists!A5 -> East | B6: =SUMIFS(tx_Total,tx_Region,$A6,tx_Category,B$4) -> 2239.67 | C6: =SUMIFS(tx_Total,tx_Region,$A6,tx_Category,C$4) -> 50649.01 | D6: =SUMIFS(tx_Total,tx_Region,$A6,tx_Category,D$4) -> 6399.71 | E6: =SUM(B6:D6) -> 59288.39 | J6: =EDATE(J5,1) -> 45413 | K6: =EOMONTH(J6,0) -> 45443 | L6: =SUMIFS(tx_Total,tx_Date,">="&J6,tx_Date,"<="&K6) -> 17039.35 | M6: =COUNTIFS(tx_Date,">="&J6,tx_Date,"<="&K6) -> 19 | N6: =SUMIFS(tx_Qty,tx_Date,">="&J6,tx_Date,"<="&K6) -> 65 | O6: =IF(L5=0,"",L6/L5-1) -> -0.18547344 | P6: =IF(AND(MIN(tx_Date)<=J6,MAX(tx_Date)>=K6),"Full","Partial") -> Full | Q6: =TEXT(J6,"mmm-yy") -> May-24
A7: =Lists!A6 -> North | B7: =SUMIFS(tx_Total,tx_Region,$A7,tx_Category,B$4) -> 1119.84 | C7: =SUMIFS(tx_Total,tx_Region,$A7,tx_Category,C$4) -> 39239.04 | D7: =SUMIFS(tx_Total,tx_Region,$A7,tx_Category,D$4) -> 10449.43 | E7: =SUM(B7:D7) -> 50808.31 | J7: =EDATE(J6,1) -> 45444 | K7: =EOMONTH(J7,0) -> 45473 | L7: =SUMIFS(tx_Total,tx_Date,">="&J7,tx_Date,"<="&K7) -> 19299.45 | M7: =COUNTIFS(tx_Date,">="&J7,tx_Date,"<="&K7) -> 19 | N7: =SUMIFS(tx_Qty,tx_Date,">="&J7,tx_Date,"<="&K7) -> 55 | O7: =IF(L6=0,"",L7/L6-1) -> 0.13264004 | P7: =IF(AND(MIN(tx_Date)<=J7,MAX(tx_Date)>=K7),"Full","Partial") -> Full | Q7: =TEXT(J7,"mmm-yy") -> Jun-24
A8: =Lists!A7 -> South | B8: =SUMIFS(tx_Total,tx_Region,$A8,tx_Category,B$4) -> 1099.83 | C8: =SUMIFS(tx_Total,tx_Region,$A8,tx_Category,C$4) -> 25549.32 | D8: =SUMIFS(tx_Total,tx_Region,$A8,tx_Category,D$4) -> 9749.6 | E8: =SUM(B8:D8) -> 36398.75 | J8: =EDATE(J7,1) -> 45474 | K8: =EOMONTH(J8,0) -> 45504 | L8: =SUMIFS(tx_Total,tx_Date,">="&J8,tx_Date,"<="&K8) -> 18479.4 | M8: =COUNTIFS(tx_Date,">="&J8,tx_Date,"<="&K8) -> 24 | N8: =SUMIFS(tx_Qty,tx_Date,">="&J8,tx_Date,"<="&K8) -> 60 | O8: =IF(L7=0,"",L8/L7-1) -> -0.042490848 | P8: =IF(AND(MIN(tx_Date)<=J8,MAX(tx_Date)>=K8),"Full","Partial") -> Full | Q8: =TEXT(J8,"mmm-yy") -> Jul-24
A9: =Lists!A8 -> West | B9: =SUMIFS(tx_Total,tx_Region,$A9,tx_Category,B$4) -> 1879.69 | C9: =SUMIFS(tx_Total,tx_Region,$A9,tx_Category,C$4) -> 31429.35 | D9: =SUMIFS(tx_Total,tx_Region,$A9,tx_Category,D$4) -> 8099.64 | E9: =SUM(B9:D9) -> 41408.68 | J9: =EDATE(J8,1) -> 45505 | K9: =EOMONTH(J9,0) -> 45535 | L9: =SUMIFS(tx_Total,tx_Date,">="&J9,tx_Date,"<="&K9) -> 15759.43 | M9: =COUNTIFS(tx_Date,">="&J9,tx_Date,"<="&K9) -> 18 | N9: =SUMIFS(tx_Qty,tx_Date,">="&J9,tx_Date,"<="&K9) -> 57 | O9: =IF(L8=0,"",L9/L8-1) -> -0.1471893 | P9: =IF(AND(MIN(tx_Date)<=J9,MAX(tx_Date)>=K9),"Full","Partial") -> Full | Q9: =TEXT(J9,"mmm-yy") -> Aug-24
A10: Total | B10: =SUM(B5:B9) -> 8338.74 | C10: =SUM(C5:C9) -> 171756.05 | D10: =SUM(D5:D9) -> 49097.68 | E10: =SUM(E5:E9) -> 229192.47 | J10: =EDATE(J9,1) -> 45536 | K10: =EOMONTH(J10,0) -> 45565 | L10: =SUMIFS(tx_Total,tx_Date,">="&J10,tx_Date,"<="&K10) -> 12989.51 | M10: =COUNTIFS(tx_Date,">="&J10,tx_Date,"<="&K10) -> 19 | N10: =SUMIFS(tx_Qty,tx_Date,">="&J10,tx_Date,"<="&K10) -> 49 | O10: =IF(L9=0,"",L10/L9-1) -> -0.1757627 | P10: =IF(AND(MIN(tx_Date)<=J10,MAX(tx_Date)>=K10),"Full","Partial") -> Full | Q10: =TEXT(J10,"mmm-yy") -> Sep-24
J11: =EDATE(J10,1) -> 45566 | K11: =EOMONTH(J11,0) -> 45596 | L11: =SUMIFS(tx_Total,tx_Date,">="&J11,tx_Date,"<="&K11) -> 20609.52 | M11: =COUNTIFS(tx_Date,">="&J11,tx_Date,"<="&K11) -> 16 | N11: =SUMIFS(tx_Qty,tx_Date,">="&J11,tx_Date,"<="&K11) -> 48 | O11: =IF(L10=0,"",L11/L10-1) -> 0.58662798 | P11: =IF(AND(MIN(tx_Date)<=J11,MAX(tx_Date)>=K11),"Full","Partial") -> Full | Q11: =TEXT(J11,"mmm-yy") -> Oct-24
J12: =EDATE(J11,1) -> 45597 | K12: =EOMONTH(J12,0) -> 45626 | L12: =SUMIFS(tx_Total,tx_Date,">="&J12,tx_Date,"<="&K12) -> 12309.44 | M12: =COUNTIFS(tx_Date,">="&J12,tx_Date,"<="&K12) -> 17 | N12: =SUMIFS(tx_Qty,tx_Date,">="&J12,tx_Date,"<="&K12) -> 56 | O12: =IF(L11=0,"",L12/L11-1) -> -0.40273039 | P12: =IF(AND(MIN(tx_Date)<=J12,MAX(tx_Date)>=K12),"Full","Partial") -> Full | Q12: =TEXT(J12,"mmm-yy") -> Nov-24
A13: Region summary | J13: =EDATE(J12,1) -> 45627 | K13: =EOMONTH(J13,0) -> 45657 | L13: =SUMIFS(tx_Total,tx_Date,">="&J13,tx_Date,"<="&K13) -> 23039.3 | M13: =COUNTIFS(tx_Date,">="&J13,tx_Date,"<="&K13) -> 25 | N13: =SUMIFS(tx_Qty,tx_Date,">="&J13,tx_Date,"<="&K13) -> 70 | O13: =IF(L12=0,"",L13/L12-1) -> 0.87167735 | P13: =IF(AND(MIN(tx_Date)<=J13,MAX(tx_Date)>=K13),"Full","Partial") -> Full | Q13: =TEXT(J13,"mmm-yy") -> Dec-24
A14: Region | B14: Revenue | C14: Transactions | D14: Units | E14: Avg Order Value | F14: Share of Revenue | G14: Rank | J14: =EDATE(J13,1) -> 45658 | K14: =EOMONTH(J14,0) -> 45688 | L14: =SUMIFS(tx_Total,tx_Date,">="&J14,tx_Date,"<="&K14) -> 25799.15 | M14: =COUNTIFS(tx_Date,">="&J14,tx_Date,"<="&K14) -> 26 | N14: =SUMIFS(tx_Qty,tx_Date,">="&J14,tx_Date,"<="&K14) -> 85 | O14: =IF(L13=0,"",L14/L13-1) -> 0.1197888 | P14: =IF(AND(MIN(tx_Date)<=J14,MAX(tx_Date)>=K14),"Full","Partial") -> Full | Q14: =TEXT(J14,"mmm-yy") -> Jan-25
A15: =Lists!A4 -> Central | B15: =SUMIFS(tx_Total,tx_Region,$A15) -> 41288.34 | C15: =COUNTIFS(tx_Region,$A15) -> 54 | D15: =SUMIFS(tx_Qty,tx_Region,$A15) -> 166 | E15: =IF(C15=0,0,B15/C15) -> 764.59889 | F15: =B15/$B$20 -> 0.18014702 | G15: =RANK(B15,$B$15:$B$19,0)+COUNTIF($B$15:B15,B15)-1 -> 4 | J15: =EDATE(J14,1) -> 45689 | K15: =EOMONTH(J15,0) -> 45716 | L15: =SUMIFS(tx_Total,tx_Date,">="&J15,tx_Date,"<="&K15) -> 16069.38 | M15: =COUNTIFS(tx_Date,">="&J15,tx_Date,"<="&K15) -> 20 | N15: =SUMIFS(tx_Qty,tx_Date,">="&J15,tx_Date,"<="&K15) -> 62 | O15: =IF(L14=0,"",L15/L14-1) -> -0.37713529 | P15: =IF(AND(MIN(tx_Date)<=J15,MAX(tx_Date)>=K15),"Full","Partial") -> Full | Q15: =TEXT(J15,"mmm-yy") -> Feb-25
A16: =Lists!A5 -> East | B16: =SUMIFS(tx_Total,tx_Region,$A16) -> 59288.39 | C16: =COUNTIFS(tx_Region,$A16) -> 48 | D16: =SUMIFS(tx_Qty,tx_Region,$A16) -> 161 | E16: =IF(C16=0,0,B16/C16) -> 1235.1748 | F16: =B16/$B$20 -> 0.25868385 | G16: =RANK(B16,$B$15:$B$19,0)+COUNTIF($B$15:B16,B16)-1 -> 1 | J16: =EDATE(J15,1) -> 45717 | K16: =EOMONTH(J16,0) -> 45747 | L16: =SUMIFS(tx_Total,tx_Date,">="&J16,tx_Date,"<="&K16) -> 19899.38 | M16: =COUNTIFS(tx_Date,">="&J16,tx_Date,"<="&K16) -> 19 | N16: =SUMIFS(tx_Qty,tx_Date,">="&J16,tx_Date,"<="&K16) -> 62 | O16: =IF(L15=0,"",L16/L15-1) -> 0.23834149 | P16: =IF(AND(MIN(tx_Date)<=J16,MAX(tx_Date)>=K16),"Full","Partial") -> Full | Q16: =TEXT(J16,"mmm-yy") -> Mar-25
A17: =Lists!A6 -> North | B17: =SUMIFS(tx_Total,tx_Region,$A17) -> 50808.31 | C17: =COUNTIFS(tx_Region,$A17) -> 59 | D17: =SUMIFS(tx_Qty,tx_Region,$A17) -> 169 | E17: =IF(C17=0,0,B17/C17) -> 861.1578 | F17: =B17/$B$20 -> 0.22168403 | G17: =RANK(B17,$B$15:$B$19,0)+COUNTIF($B$15:B17,B17)-1 -> 2 | J17: =EDATE(J16,1) -> 45748 | K17: =EOMONTH(J17,0) -> 45777 | L17: =SUMIFS(tx_Total,tx_Date,">="&J17,tx_Date,"<="&K17) -> 6979.83 | M17: =COUNTIFS(tx_Date,">="&J17,tx_Date,"<="&K17) -> 7 | N17: =SUMIFS(tx_Qty,tx_Date,">="&J17,tx_Date,"<="&K17) -> 17 | O17: =IF(L16=0,"",L17/L16-1) -> -0.64924385 | P17: =IF(AND(MIN(tx_Date)<=J17,MAX(tx_Date)>=K17),"Full","Partial") -> Partial | Q17: =TEXT(J17,"mmm-yy") -> Apr-25
A18: =Lists!A7 -> South | B18: =SUMIFS(tx_Total,tx_Region,$A18) -> 36398.75 | C18: =COUNTIFS(tx_Region,$A18) -> 42 | D18: =SUMIFS(tx_Qty,tx_Region,$A18) -> 125 | E18: =IF(C18=0,0,B18/C18) -> 866.6369 | F18: =B18/$B$20 -> 0.15881303 | G18: =RANK(B18,$B$15:$B$19,0)+COUNTIF($B$15:B18,B18)-1 -> 5 | J18: Total | L18: =SUM(L5:L17) -> 229192.47 | M18: =SUM(M5:M17) -> 250 | N18: =SUM(N5:N17) -> 753
A19: =Lists!A8 -> West | B19: =SUMIFS(tx_Total,tx_Region,$A19) -> 41408.68 | C19: =COUNTIFS(tx_Region,$A19) -> 47 | D19: =SUMIFS(tx_Qty,tx_Region,$A19) -> 132 | E19: =IF(C19=0,0,B19/C19) -> 881.03574 | F19: =B19/$B$20 -> 0.18067208 | G19: =RANK(B19,$B$15:$B$19,0)+COUNTIF($B$15:B19,B19)-1 -> 3
A20: Total | B20: =SUM(B15:B19) -> 229192.47 | C20: =SUM(C15:C19) -> 250 | D20: =SUM(D15:D19) -> 753 | E20: =B20/C20 -> 916.76988 | F20: =SUM(F15:F19) -> 1
A23: Category summary
A24: Category | B24: Revenue | C24: Transactions | D24: Units | E24: Avg Order Value | F24: Share of Revenue
A25: =Lists!B4 -> Appliances | B25: =SUMIFS(tx_Total,tx_Category,$A25) -> 8338.74 | C25: =COUNTIFS(tx_Category,$A25) -> 43 | D25: =SUMIFS(tx_Qty,tx_Category,$A25) -> 126 | E25: =IF(C25=0,0,B25/C25) -> 193.92419 | F25: =B25/B$28 -> 0.036383132
A26: =Lists!B5 -> Electronics | B26: =SUMIFS(tx_Total,tx_Category,$A26) -> 171756.05 | C26: =COUNTIFS(tx_Category,$A26) -> 131 | D26: =SUMIFS(tx_Qty,tx_Category,$A26) -> 395 | E26: =IF(C26=0,0,B26/C26) -> 1311.1149 | F26: =B26/B$28 -> 0.74939657
A27: =Lists!B6 -> Furniture | B27: =SUMIFS(tx_Total,tx_Category,$A27) -> 49097.68 | C27: =COUNTIFS(tx_Category,$A27) -> 76 | D27: =SUMIFS(tx_Qty,tx_Category,$A27) -> 232 | E27: =IF(C27=0,0,B27/C27) -> 646.02211 | F27: =B27/B$28 -> 0.2142203
A28: Total | B28: =SUM(B25:B27) -> 229192.47 | C28: =SUM(C25:C27) -> 250 | D28: =SUM(D25:D27) -> 753 | E28: =B28/C28 -> 916.76988 | F28: =SUM(F25:F27) -> 1
A31: Payment method summary
A32: Payment_Method | B32: Revenue | C32: Transactions | D32: Units | E32: Avg Order Value | F32: Share of Revenue
A33: =Lists!E4 -> Cash | B33: =SUMIFS(tx_Total,tx_Pay,$A33) -> 57427.79 | C33: =COUNTIFS(tx_Pay,$A33) -> 76 | D33: =SUMIFS(tx_Qty,tx_Pay,$A33) -> 221 | E33: =IF(C33=0,0,B33/C33) -> 755.62882 | F33: =B33/B$37 -> 0.25056578
A34: =Lists!E5 -> Credit Card | B34: =SUMIFS(tx_Total,tx_Pay,$A34) -> 61447.96 | C34: =COUNTIFS(tx_Pay,$A34) -> 68 | D34: =SUMIFS(tx_Qty,tx_Pay,$A34) -> 204 | E34: =IF(C34=0,0,B34/C34) -> 903.64647 | F34: =B34/B$37 -> 0.26810636
A35: =Lists!E6 -> Debit Card | B35: =SUMIFS(tx_Total,tx_Pay,$A35) -> 52118.31 | C35: =COUNTIFS(tx_Pay,$A35) -> 54 | D35: =SUMIFS(tx_Qty,tx_Pay,$A35) -> 169 | E35: =IF(C35=0,0,B35/C35) -> 965.15389 | F35: =B35/B$37 -> 0.22739975
A36: =Lists!E7 -> PayPal | B36: =SUMIFS(tx_Total,tx_Pay,$A36) -> 58198.41 | C36: =COUNTIFS(tx_Pay,$A36) -> 52 | D36: =SUMIFS(tx_Qty,tx_Pay,$A36) -> 159 | E36: =IF(C36=0,0,B36/C36) -> 1119.2002 | F36: =B36/B$37 -> 0.25392811
A37: Total | B37: =SUM(B33:B36) -> 229192.47 | C37: =SUM(C33:C36) -> 250 | D37: =SUM(D33:D36) -> 753 | E37: =B37/C37 -> 916.76988 | F37: =SUM(F33:F36) -> 1
A40: Customer segment summary
A41: Customer_Segment | B41: Revenue | C41: Transactions | D41: Units | E41: Avg Order Value | F41: Share of Revenue
A42: =Lists!F4 -> Basic | B42: =SUMIFS(tx_Total,tx_Segment,$A42) -> 62177.81 | C42: =COUNTIFS(tx_Segment,$A42) -> 74 | D42: =SUMIFS(tx_Qty,tx_Segment,$A42) -> 219 | E42: =IF(C42=0,0,B42/C42) -> 840.24068 | F42: =B42/B$45 -> 0.27129081
A43: =Lists!F5 -> Premium | B43: =SUMIFS(tx_Total,tx_Segment,$A43) -> 84657.12 | C43: =COUNTIFS(tx_Segment,$A43) -> 95 | D43: =SUMIFS(tx_Qty,tx_Segment,$A43) -> 288 | E43: =IF(C43=0,0,B43/C43) -> 891.12758 | F43: =B43/B$45 -> 0.3693713
A44: =Lists!F6 -> Standard | B44: =SUMIFS(tx_Total,tx_Segment,$A44) -> 82357.54 | C44: =COUNTIFS(tx_Segment,$A44) -> 81 | D44: =SUMIFS(tx_Qty,tx_Segment,$A44) -> 246 | E44: =IF(C44=0,0,B44/C44) -> 1016.7598 | F44: =B44/B$45 -> 0.3593379
A45: Total | B45: =SUM(B42:B44) -> 229192.47 | C45: =SUM(C42:C44) -> 250 | D45: =SUM(D42:D44) -> 753 | E45: =B45/C45 -> 916.76988 | F45: =SUM(F42:F44) -> 1

Sheet Filter_Tool
A3: Region | B3: East
A4: Category | B4: Electronics
A5: Min Total_Amount | B5: 2000
A6: Matching transactions | B6: =MAX($N$10:$N$259) -> 11
A7: Revenue of matches | B7: =SUMPRODUCT($M$10:$M$259,tx_Total) -> 38899.53
A9: Sr. no | B9: Transaction_ID | C9: Date | D9: Customer_Name | E9: Product_Name | F9: Category | G9: Region | H9: Quantity | I9: Total_Amount | J9: Source row | L9: Helper: idx | M9: Helper: match | N9: Helper: running
A10: =IF(ROWS($A$10:A10)<=$B$6,ROWS($A$10:A10),"") -> 1 | B10: {=IF($J10="","",INDEX(tx_ID,$J10))} -> TRX0135 | C10: {=IF($J10="","",INDEX(tx_Date,$J10))} -> 45405 | D10: {=IF($J10="","",INDEX(tx_CustName,$J10))} -> Robert Thomas | E10: {=IF($J10="","",INDEX(tx_Product,$J10))} -> Laptop | F10: {=IF($J10="","",INDEX(tx_Category,$J10))} -> Electronics | G10: {=IF($J10="","",INDEX(tx_Region,$J10))} -> East | H10: {=IF($J10="","",INDEX(tx_Qty,$J10))} -> 3 | I10: {=IF($J10="","",INDEX(tx_Total,$J10))} -> 2699.97 | J10: =IF($A10="","",MATCH($A10,$N$10:$N$259,0)) -> 9 | L10: =ROW()-ROW($L$9) -> 1 | M10: {=IF(AND(OR($B$3="All",INDEX(tx_Region,L10)=$B$3),OR($B$4="All",INDEX(tx_Category,L10)=$B$4),INDEX(tx_Total,L10)>=$B$5),1,0)} -> 0 | N10: =M10 -> 0
A11: =IF(ROWS($A$10:A11)<=$B$6,ROWS($A$10:A11),"") -> 2 | B11: {=IF($J11="","",INDEX(tx_ID,$J11))} -> TRX0239 | C11: {=IF($J11="","",INDEX(tx_Date,$J11))} -> 45413 | D11: {=IF($J11="","",INDEX(tx_CustName,$J11))} -> Patricia Moore | E11: {=IF($J11="","",INDEX(tx_Product,$J11))} -> Smartphone | F11: {=IF($J11="","",INDEX(tx_Category,$J11))} -> Electronics | G11: {=IF($J11="","",INDEX(tx_Region,$J11))} -> East | H11: {=IF($J11="","",INDEX(tx_Qty,$J11))} -> 4 | I11: {=IF($J11="","",INDEX(tx_Total,$J11))} -> 2799.96 | J11: =IF($A11="","",MATCH($A11,$N$10:$N$259,0)) -> 22 | L11: =ROW()-ROW($L$9) -> 2 | M11: {=IF(AND(OR($B$3="All",INDEX(tx_Region,L11)=$B$3),OR($B$4="All",INDEX(tx_Category,L11)=$B$4),INDEX(tx_Total,L11)>=$B$5),1,0)} -> 0 | N11: =N10+M11 -> 0
A12: =IF(ROWS($A$10:A12)<=$B$6,ROWS($A$10:A12),"") -> 3 | B12: {=IF($J12="","",INDEX(tx_ID,$J12))} -> TRX0044 | C12: {=IF($J12="","",INDEX(tx_Date,$J12))} -> 45459 | D12: {=IF($J12="","",INDEX(tx_CustName,$J12))} -> Edward Mitchell | E12: {=IF($J12="","",INDEX(tx_Product,$J12))} -> Laptop | F12: {=IF($J12="","",INDEX(tx_Category,$J12))} -> Electronics | G12: {=IF($J12="","",INDEX(tx_Region,$J12))} -> East | H12: {=IF($J12="","",INDEX(tx_Qty,$J12))} -> 5 | I12: {=IF($J12="","",INDEX(tx_Total,$J12))} -> 4499.95 | J12: =IF($A12="","",MATCH($A12,$N$10:$N$259,0)) -> 51 | L12: =ROW()-ROW($L$9) -> 3 | M12: {=IF(AND(OR($B$3="All",INDEX(tx_Region,L12)=$B$3),OR($B$4="All",INDEX(tx_Category,L12)=$B$4),INDEX(tx_Total,L12)>=$B$5),1,0)} -> 0 | N12: =N11+M12 -> 0
